Workbook

Sheet Title
A1: A Study on the Impact of COVID-19 on Digital Payment Behaviour Among Customers in India: A Case Study of UPI
A4: Details | C4: Information
A5: Prepared By | C5: Ancilla Fiona Dsouza
A6: Course | C6: Bcom
A7: Data Source | C7: NPCI Website
A8: Data Type | C8: Secondary Data
A9: Period of Study | C9: April 2025 - June 2025
A11: Source: National Payments Corporation of India (NPCI)
A12: Link : | B12: https://www.npci.org.in/product/upi/product-statistics

Sheet Product Statistics-19-20
A1: Month | B1: No. of Banks live on UPI | C1: Volume (In Mn.) | D1: Value (In Cr.) | E1: Period | F1: Vol Growth % | G1: Value Growth %
A2: 43556 | B2: 144 | C2: 781.79 | D2: 142034.39 | E2: Pre-COVID | F2: NA | G2: NA
A3: 43586 | B3: 143 | C3: 733.54 | D3: 152449.29 | E3: Pre-COVID | F3: =(Table2[[#This Row],[Volume (In Mn.)]]-C2)/C2*100 -> -6.1717341 | G3: =(Table2[[#This Row],[Value (In Cr.)]]-D2)/D2*100 -> 7.3326608
A4: 43617 | B4: 142 | C4: 754.54 | D4: 146566.35 | E4: Pre-COVID | F4: =(Table2[[#This Row],[Volume (In Mn.)]]-C3)/C3*100 -> 2.8628296 | G4: =(Table2[[#This Row],[Value (In Cr.)]]-D3)/D3*100 -> -3.8589488
A5: 43647 | B5: 143 | C5: 822.29 | D5: 146386.64 | E5: Pre-COVID | F5: =(Table2[[#This Row],[Volume (In Mn.)]]-C4)/C4*100 -> 8.9789806 | G5: =(Table2[[#This Row],[Value (In Cr.)]]-D4)/D4*100 -> -0.12261341
A6: 43678 | B6: 141 | C6: 918.35 | D6: 154504.89 | E6: Pre-COVID | F6: =(Table2[[#This Row],[Volume (In Mn.)]]-C5)/C5*100 -> 11.68201 | G6: =(Table2[[#This Row],[Value (In Cr.)]]-D5)/D5*100 -> 5.5457588
A7: 43709 | B7: 141 | C7: 955.02 | D7: 161456.56 | E7: Pre-COVID | F7: =(Table2[[#This Row],[Volume (In Mn.)]]-C6)/C6*100 -> 3.993031 | G7: =(Table2[[#This Row],[Value (In Cr.)]]-D6)/D6*100 -> 4.4993204
A8: 43739 | B8: 141 | C8: 1148.36 | D8: 191359.94 | E8: Pre-COVID | F8: =(Table2[[#This Row],[Volume (In Mn.)]]-C7)/C7*100 -> 20.244602 | G8: =(Table2[[#This Row],[Value (In Cr.)]]-D7)/D7*100 -> 18.521007
A9: 43770 | B9: 143 | C9: 1218.77 | D9: 189229.09 | E9: Pre-COVID | F9: =(Table2[[#This Row],[Volume (In Mn.)]]-C8)/C8*100 -> 6.1313525 | G9: =(Table2[[#This Row],[Value (In Cr.)]]-D8)/D8*100 -> -1.1135298
A10: 43800 | B10: 143 | C10: 1308.4 | D10: 202520.76 | E10: Pre-COVID | F10: =(Table2[[#This Row],[Volume (In Mn.)]]-C9)/C9*100 -> 7.3541357 | G10: =(Table2[[#This Row],[Value (In Cr.)]]-D9)/D9*100 -> 7.0241156
A11: 43831 | B11: 144 | C11: 1305.02 | D11: 216242.97 | E11: Pre-COVID | F11: =(Table2[[#This Row],[Volume (In Mn.)]]-C10)/C10*100 -> -0.25833079 | G11: =(Table2[[#This Row],[Value (In Cr.)]]-D10)/D10*100 -> 6.7757054
A12: 43862 | B12: 146 | C12: 1325.69 | D12: 222516.95 | E12: Pre-COVID | F12: =(Table2[[#This Row],[Volume (In Mn.)]]-C11)/C11*100 -> 1.5838838 | G12: =(Table2[[#This Row],[Value (In Cr.)]]-D11)/D11*100 -> 2.9013567
A13: 43891 | B13: 148 | C13: 1246.84 | D13: 206462.31 | E13: Pre-COVID | F13: =(Table2[[#This Row],[Volume (In Mn.)]]-C12)/C12*100 -> -5.947846 | G13: =(Table2[[#This Row],[Value (In Cr.)]]-D12)/D12*100 -> -7.2150189

Sheet Product Statistics-20-21
A1: Month | B1: No. of Banks live on UPI | C1: Volume (In Mn.) | D1: Value (In Cr.) | E1: Period | F1: Vol Growth % | G1: Value Growth %
A2: 43922 | B2: 153 | C2: 999.57 | D2: 151140.66 | E2: COVID | F2: NA | G2: NA
A3: 43952 | B3: 155 | C3: 1234.5 | D3: 218391.6 | E3: COVID | F3: =(Table3[[#This Row],[Volume (In Mn.)]]-C2)/C2*100 -> 23.503106 | G3: =(Table3[[#This Row],[Value (In Cr.)]]-D2)/D2*100 -> 44.495598
A4: 43983 | B4: 155 | C4: 1336.93 | D4: 261835 | E4: COVID | F4: =(Table3[[#This Row],[Volume (In Mn.)]]-C3)/C3*100 -> 8.2972864 | G4: =(Table3[[#This Row],[Value (In Cr.)]]-D3)/D3*100 -> 19.892432
A5: 44013 | B5: 164 | C5: 1497.36 | D5: 290537.86 | E5: COVID | F5: =(Table3[[#This Row],[Volume (In Mn.)]]-C4)/C4*100 -> 11.99988 | G5: =(Table3[[#This Row],[Value (In Cr.)]]-D4)/D4*100 -> 10.962194
A6: 44044 | B6: 168 | C6: 1618.83 | D6: 298307.61 | E6: COVID | F6: =(Table3[[#This Row],[Volume (In Mn.)]]-C5)/C5*100 -> 8.1122776 | G6: =(Table3[[#This Row],[Value (In Cr.)]]-D5)/D5*100 -> 2.6742642
A7: 44075 | B7: 174 | C7: 1800.14 | D7: 329027.66 | E7: COVID | F7: =(Table3[[#This Row],[Volume (In Mn.)]]-C6)/C6*100 -> 11.200064 | G7: =(Table3[[#This Row],[Value (In Cr.)]]-D6)/D6*100 -> 10.298111
A8: 44105 | B8: 189 | C8: 2071.62 | D8: 386106.74 | E8: COVID | F8: =(Table3[[#This Row],[Volume (In Mn.)]]-C7)/C7*100 -> 15.081049 | G8: =(Table3[[#This Row],[Value (In Cr.)]]-D7)/D7*100 -> 17.347806
A9: 44136 | B9: 200 | C9: 2210.23 | D9: 390999.15 | E9: COVID | F9: =(Table3[[#This Row],[Volume (In Mn.)]]-C8)/C8*100 -> 6.6908989 | G9: =(Table3[[#This Row],[Value (In Cr.)]]-D8)/D8*100 -> 1.2671133
A10: 44166 | B10: 207 | C10: 2234.16 | D10: 416176.21 | E10: COVID | F10: =(Table3[[#This Row],[Volume (In Mn.)]]-C9)/C9*100 -> 1.0826928 | G10: =(Table3[[#This Row],[Value (In Cr.)]]-D9)/D9*100 -> 6.4391598
A11: 44197 | B11: 207 | C11: 2302.73 | D11: 431181.89 | E11: COVID | F11: =(Table3[[#This Row],[Volume (In Mn.)]]-C10)/C10*100 -> 3.0691625 | G11: =(Table3[[#This Row],[Value (In Cr.)]]-D10)/D10*100 -> 3.6056073
A12: 44228 | B12: 213 | C12: 2292.9 | D12: 425062.76 | E12: COVID | F12: =(Table3[[#This Row],[Volume (In Mn.)]]-C11)/C11*100 -> -0.42688461 | G12: =(Table3[[#This Row],[Value (In Cr.)]]-D11)/D11*100 -> -1.4191528
A13: 44256 | B13: 216 | C13: 2731.68 | D13: 504886.44 | E13: COVID | F13: =(Table3[[#This Row],[Volume (In Mn.)]]-C12)/C12*100 -> 19.136465 | G13: =(Table3[[#This Row],[Value (In Cr.)]]-D12)/D12*100 -> 18.779269

Sheet Combined Data
A1: Month | B1: No. of Banks live on UPI | C1: Volume (In Mn.) | D1: Value (In Cr.) | E1: Period | F1: Vol Growth % | G1: Value Growth %
A2: 43556 | B2: 144 | C2: 781.79 | D2: 142034.39 | E2: Pre-COVID | F2: NA | G2: NA
A3: 43586 | B3: 146 | C3: 733.54 | D3: 152449.29 | E3: Pre-COVID | F3: =(Table4[[#This Row],[Volume (In Mn.)]]-C2)/C2*100 -> -6.1717341 | G3: =(Table4[[#This Row],[Value (In Cr.)]]-D2)/D2*100 -> 7.3326608
A4: 43617 | B4: 142 | C4: 754.54 | D4: 146566.35 | E4: Pre-COVID | F4: =(Table4[[#This Row],[Volume (In Mn.)]]-C3)/C3*100 -> 2.8628296 | G4: =(Table4[[#This Row],[Value (In Cr.)]]-D3)/D3*100 -> -3.8589488
A5: 43647 | B5: 143 | C5: 822.29 | D5: 146386.64 | E5: Pre-COVID | F5: =(Table4[[#This Row],[Volume (In Mn.)]]-C4)/C4*100 -> 8.9789806 | G5: =(Table4[[#This Row],[Value (In Cr.)]]-D4)/D4*100 -> -0.12261341
A6: 43678 | B6: 141 | C6: 918.35 | D6: 154504.89 | E6: Pre-COVID | F6: =(Table4[[#This Row],[Volume (In Mn.)]]-C5)/C5*100 -> 11.68201 | G6: =(Table4[[#This Row],[Value (In Cr.)]]-D5)/D5*100 -> 5.5457588
A7: 43709 | B7: 141 | C7: 955.02 | D7: 161456.56 | E7: Pre-COVID | F7: =(Table4[[#This Row],[Volume (In Mn.)]]-C6)/C6*100 -> 3.993031 | G7: =(Table4[[#This Row],[Value (In Cr.)]]-D6)/D6*100 -> 4.4993204
A8: 43739 | B8: 141 | C8: 1148.36 | D8: 191359.94 | E8: Pre-COVID | F8: =(Table4[[#This Row],[Volume (In Mn.)]]-C7)/C7*100 -> 20.244602 | G8: =(Table4[[#This Row],[Value (In Cr.)]]-D7)/D7*100 -> 18.521007
A9: 43770 | B9: 143 | C9: 1218.77 | D9: 189229.09 | E9: Pre-COVID | F9: =(Table4[[#This Row],[Volume (In Mn.)]]-C8)/C8*100 -> 6.1313525 | G9: =(Table4[[#This Row],[Value (In Cr.)]]-D8)/D8*100 -> -1.1135298
A10: 43800 | B10: 143 | C10: 1308.4 | D10: 202520.76 | E10: Pre-COVID | F10: =(Table4[[#This Row],[Volume (In Mn.)]]-C9)/C9*100 -> 7.3541357 | G10: =(Table4[[#This Row],[Value (In Cr.)]]-D9)/D9*100 -> 7.0241156
A11: 43831 | B11: 144 | C11: 1305.02 | D11: 216242.97 | E11: Pre-COVID | F11: =(Table4[[#This Row],[Volume (In Mn.)]]-C10)/C10*100 -> -0.25833079 | G11: =(Table4[[#This Row],[Value (In Cr.)]]-D10)/D10*100 -> 6.7757054
A12: 43862 | B12: 146 | C12: 1325.69 | D12: 222516.95 | E12: Pre-COVID | F12: =(Table4[[#This Row],[Volume (In Mn.)]]-C11)/C11*100 -> 1.5838838 | G12: =(Table4[[#This Row],[Value (In Cr.)]]-D11)/D11*100 -> 2.9013567
A13: 43891 | B13: 148 | C13: 1246.84 | D13: 206462.31 | E13: Pre-COVID | F13: =(Table4[[#This Row],[Volume (In Mn.)]]-C12)/C12*100 -> -5.947846 | G13: =(Table4[[#This Row],[Value (In Cr.)]]-D12)/D12*100 -> -7.2150189
A14: 43922 | B14: 153 | C14: 999.57 | D14: 151140.66 | E14: COVID | F14: NA | G14: NA
A15: 43952 | B15: 155 | C15: 1234.5 | D15: 218391.6 | E15: COVID | F15: =(Table4[[#This Row],[Volume (In Mn.)]]-C14)/C14*100 -> 23.503106 | G15: =(Table4[[#This Row],[Value (In Cr.)]]-D14)/D14*100 -> 44.495598
A16: 43983 | B16: 155 | C16: 1336.93 | D16: 261835 | E16: COVID | F16: =(Table4[[#This Row],[Volume (In Mn.)]]-C15)/C15*100 -> 8.2972864 | G16: =(Table4[[#This Row],[Value (In Cr.)]]-D15)/D15*100 -> 19.892432
A17: 44013 | B17: 164 | C17: 1497.36 | D17: 290537.86 | E17: COVID | F17: =(Table4[[#This Row],[Volume (In Mn.)]]-C16)/C16*100 -> 11.99988 | G17: =(Table4[[#This Row],[Value (In Cr.)]]-D16)/D16*100 -> 10.962194
A18: 44044 | B18: 168 | C18: 1618.83 | D18: 298307.61 | E18: COVID | F18: =(Table4[[#This Row],[Volume (In Mn.)]]-C17)/C17*100 -> 8.1122776 | G18: =(Table4[[#This Row],[Value (In Cr.)]]-D17)/D17*100 -> 2.6742642
A19: 44075 | B19: 174 | C19: 1800.14 | D19: 329027.66 | E19: COVID | F19: =(Table4[[#This Row],[Volume (In Mn.)]]-C18)/C18*100 -> 11.200064 | G19: =(Table4[[#This Row],[Value (In Cr.)]]-D18)/D18*100 -> 10.298111
A20: 44105 | B20: 189 | C20: 2071.62 | D20: 386106.74 | E20: COVID | F20: =(Table4[[#This Row],[Volume (In Mn.)]]-C19)/C19*100 -> 15.081049 | G20: =(Table4[[#This Row],[Value (In Cr.)]]-D19)/D19*100 -> 17.347806
A21: 44136 | B21: 200 | C21: 2210.23 | D21: 390999.15 | E21: COVID | F21: =(Table4[[#This Row],[Volume (In Mn.)]]-C20)/C20*100 -> 6.6908989 | G21: =(Table4[[#This Row],[Value (In Cr.)]]-D20)/D20*100 -> 1.2671133
A22: 44166 | B22: 207 | C22: 2234.16 | D22: 416176.21 | E22: COVID | F22: =(Table4[[#This Row],[Volume (In Mn.)]]-C21)/C21*100 -> 1.0826928 | G22: =(Table4[[#This Row],[Value (In Cr.)]]-D21)/D21*100 -> 6.4391598
A23: 44197 | B23: 207 | C23: 2302.73 | D23: 431181.89 | E23: COVID | F23: =(Table4[[#This Row],[Volume (In Mn.)]]-C22)/C22*100 -> 3.0691625 | G23: =(Table4[[#This Row],[Value (In Cr.)]]-D22)/D22*100 -> 3.6056073
A24: 44228 | B24: 213 | C24: 2292.9 | D24: 425062.76 | E24: COVID | F24: =(Table4[[#This Row],[Volume (In Mn.)]]-C23)/C23*100 -> -0.42688461 | G24: =(Table4[[#This Row],[Value (In Cr.)]]-D23)/D23*100 -> -1.4191528
A25: 44256 | B25: 216 | C25: 2731.68 | D25: 504886.44 | E25: COVID | F25: =(Table4[[#This Row],[Volume (In Mn.)]]-C24)/C24*100 -> 19.136465 | G25: =(Table4[[#This Row],[Value (In Cr.)]]-D24)/D24*100 -> 18.779269

Sheet Comparative Analysis
A1: Indicator | B1: Pre-COVID | C1: COVID
A2: Average Banks Live | B2: =AVERAGE('Combined Data'!B2:B13) -> 143.5 | C2: =AVERAGE('Combined Data'!B14:B25) -> 183.41667
A3: Average Transaction Volume | B3: =AVERAGE('Combined Data'!C2:C13) -> 1043.2175 | C3: =AVERAGE('Combined Data'!C14:C25) -> 1860.8875
A4: Average Transaction Value | B4: =AVERAGE('Combined Data'!D2:D13) -> 177644.18 | C4: =AVERAGE('Combined Data'!D14:D25) -> 341971.13
A5: Average Volume Growth % | B5: =AVERAGE('Combined Data'!F2:F13) -> 4.5866286 | C5: =AVERAGE('Combined Data'!F14:F25) -> 9.7950908
A6: Average Value Growth % | B6: =AVERAGE('Combined Data'!G2:G13) -> 3.6627103 | C6: =AVERAGE('Combined Data'!G14:G25) -> 12.212946

Sheet Graphical Representation
A1: TRENDS
A2: Volume Trend
A3: Month | B3: Volume
A4: 43556 | B4: 781.79
A5: 43586 | B5: 733.54
A6: 43617 | B6: 754.54
A7: 43647 | B7: 822.29
A8: 43678 | B8: 918.35
A9: 43709 | B9: 955.02
A10: 43739 | B10: 1148.36
A11: 43770 | B11: 1218.77
A12: 43800 | B12: 1308.4
A13: 43831 | B13: 1305.02
A14: 43862 | B14: 1325.69
A15: 43891 | B15: 1246.84
... A27: 44256 | B27: 2731.68
A30: Value Trend
A31: Month | B31: Value
A32: 43556 | B32: 142034.39
A33: 43586 | B33: 152449.29
A34: 43617 | B34: 146566.35
A35: 43647 | B35: 146386.64
A36: 43678 | B36: 154504.89
A37: 43709 | B37: 161456.56
A38: 43739 | B38: 191359.94
A39: 43770 | B39: 189229.09
A40: 43800 | B40: 202520.76
A41: 43831 | B41: 216242.97
A42: 43862 | B42: 222516.95
A43: 43891 | B43: 206462.31
... A55: 44256 | B55: 504886.44
A58: Banks Trend
A59: Month | B59: Banks Live
A60: 43556 | B60: 144
A61: 43586 | B61: 146
A62: 43617 | B62: 142
A63: 43647 | B63: 143
A64: 43678 | B64: 141
A65: 43709 | B65: 141
A66: 43739 | B66: 141
...

Sheet Summary
A1: Interpretation
A2: UPI transaction volume increased during the COVID-19 period.
A3: Transaction value showed significant growth during the pandemic.
A4: The number of banks live on UPI increased steadily.
A5: Customers preferred contactless digital payments during COVID-19.
A6: COVID-19 accelerated adoption of UPI in India.
